[2025-08-17T04:56:24.188+0000] {taskinstance.py:1159} INFO - Dependencies all met for dep_context=non-requeueable deps ti=<TaskInstance: churn_pipeline_dag.data_preparation manual__2025-08-17T04:56:15.956298+00:00 [queued]>
[2025-08-17T04:56:24.196+0000] {taskinstance.py:1159} INFO - Dependencies all met for dep_context=requeueable deps ti=<TaskInstance: churn_pipeline_dag.data_preparation manual__2025-08-17T04:56:15.956298+00:00 [queued]>
[2025-08-17T04:56:24.197+0000] {taskinstance.py:1361} INFO - Starting attempt 1 of 1
[2025-08-17T04:56:24.208+0000] {taskinstance.py:1382} INFO - Executing <Task(PythonOperator): data_preparation> on 2025-08-17 04:56:15.956298+00:00
[2025-08-17T04:56:24.216+0000] {standard_task_runner.py:57} INFO - Started process 103 to run task
[2025-08-17T04:56:24.219+0000] {standard_task_runner.py:84} INFO - Running: ['***', 'tasks', 'run', 'churn_pipeline_dag', 'data_preparation', 'manual__2025-08-17T04:56:15.956298+00:00', '--job-id', '5', '--raw', '--subdir', 'DAGS_FOLDER/churn_pipeline_dag.py', '--cfg-path', '/tmp/tmp60dqu9tu']
[2025-08-17T04:56:24.220+0000] {standard_task_runner.py:85} INFO - Job 5: Subtask data_preparation
[2025-08-17T04:56:24.270+0000] {task_command.py:415} INFO - Running <TaskInstance: churn_pipeline_dag.data_preparation manual__2025-08-17T04:56:15.956298+00:00 [running]> on host d29a9ab0bff0
[2025-08-17T04:56:24.342+0000] {taskinstance.py:1660} INFO - Exporting env vars: AIRFLOW_CTX_DAG_OWNER='***' AIRFLOW_CTX_DAG_ID='churn_pipeline_dag' AIRFLOW_CTX_TASK_ID='data_preparation' AIRFLOW_CTX_EXECUTION_DATE='2025-08-17T04:56:15.956298+00:00' AIRFLOW_CTX_TRY_NUMBER='1' AIRFLOW_CTX_DAG_RUN_ID='manual__2025-08-17T04:56:15.956298+00:00'
[2025-08-17T04:56:25.857+0000] {taskinstance.py:1943} ERROR - Task failed with exception
Traceback (most recent call last):
  File "/home/airflow/.local/lib/python3.8/site-packages/airflow/operators/python.py", line 192, in execute
    return_value = self.execute_callable()
  File "/home/airflow/.local/lib/python3.8/site-packages/airflow/operators/python.py", line 209, in execute_callable
    return self.python_callable(*self.op_args, **self.op_kwargs)
  File "/opt/airflow/dags/churn_pipeline_dag.py", line 18, in run_script
    raise Exception(f"Script failed: {script_path}\n{result.stderr}")
Exception: Script failed: /opt/***/02_Source_Code/step5_data_preparation/data_preparation.py
Traceback (most recent call last):
  File "/opt/***/02_Source_Code/step5_data_preparation/data_preparation.py", line 105, in <module>
    run()
  File "/opt/***/02_Source_Code/step5_data_preparation/data_preparation.py", line 94, in run
    df = load_latest_transactions()
  File "/opt/***/02_Source_Code/step5_data_preparation/data_preparation.py", line 30, in load_latest_transactions
    raise FileNotFoundError("No transaction files found.")
FileNotFoundError: No transaction files found.

[2025-08-17T04:56:25.880+0000] {taskinstance.py:1400} INFO - Marking task as FAILED. dag_id=churn_pipeline_dag, task_id=data_preparation, execution_date=20250817T045615, start_date=20250817T045624, end_date=20250817T045625
[2025-08-17T04:56:25.902+0000] {standard_task_runner.py:104} ERROR - Failed to execute job 5 for task data_preparation (Script failed: /opt/***/02_Source_Code/step5_data_preparation/data_preparation.py
Traceback (most recent call last):
  File "/opt/***/02_Source_Code/step5_data_preparation/data_preparation.py", line 105, in <module>
    run()
  File "/opt/***/02_Source_Code/step5_data_preparation/data_preparation.py", line 94, in run
    df = load_latest_transactions()
  File "/opt/***/02_Source_Code/step5_data_preparation/data_preparation.py", line 30, in load_latest_transactions
    raise FileNotFoundError("No transaction files found.")
FileNotFoundError: No transaction files found.
; 103)
[2025-08-17T04:56:25.919+0000] {local_task_job_runner.py:228} INFO - Task exited with return code 1
[2025-08-17T04:56:25.945+0000] {taskinstance.py:2784} INFO - 0 downstream tasks scheduled from follow-on schedule check
