[2025-08-17T02:01:12.504+0000] {taskinstance.py:1159} INFO - Dependencies all met for dep_context=non-requeueable deps ti=<TaskInstance: churn_pipeline_dag.data_ingestion manual__2025-08-17T02:01:09.990868+00:00 [queued]>
[2025-08-17T02:01:12.521+0000] {taskinstance.py:1159} INFO - Dependencies all met for dep_context=requeueable deps ti=<TaskInstance: churn_pipeline_dag.data_ingestion manual__2025-08-17T02:01:09.990868+00:00 [queued]>
[2025-08-17T02:01:12.522+0000] {taskinstance.py:1361} INFO - Starting attempt 1 of 1
[2025-08-17T02:01:12.542+0000] {taskinstance.py:1382} INFO - Executing <Task(PythonOperator): data_ingestion> on 2025-08-17 02:01:09.990868+00:00
[2025-08-17T02:01:12.553+0000] {standard_task_runner.py:57} INFO - Started process 60 to run task
[2025-08-17T02:01:12.568+0000] {standard_task_runner.py:84} INFO - Running: ['***', 'tasks', 'run', 'churn_pipeline_dag', 'data_ingestion', 'manual__2025-08-17T02:01:09.990868+00:00', '--job-id', '2', '--raw', '--subdir', 'DAGS_FOLDER/churn_pipeline_dag.py', '--cfg-path', '/tmp/tmph91pimw9']
[2025-08-17T02:01:12.571+0000] {standard_task_runner.py:85} INFO - Job 2: Subtask data_ingestion
[2025-08-17T02:01:12.715+0000] {task_command.py:415} INFO - Running <TaskInstance: churn_pipeline_dag.data_ingestion manual__2025-08-17T02:01:09.990868+00:00 [running]> on host 8ca3ef0c8fde
[2025-08-17T02:01:12.887+0000] {taskinstance.py:1660} INFO - Exporting env vars: AIRFLOW_CTX_DAG_OWNER='***' AIRFLOW_CTX_DAG_ID='churn_pipeline_dag' AIRFLOW_CTX_TASK_ID='data_ingestion' AIRFLOW_CTX_EXECUTION_DATE='2025-08-17T02:01:09.990868+00:00' AIRFLOW_CTX_TRY_NUMBER='1' AIRFLOW_CTX_DAG_RUN_ID='manual__2025-08-17T02:01:09.990868+00:00'
[2025-08-17T02:01:13.036+0000] {logging_mixin.py:151} INFO - ‚ùå Script failed: /opt/***/02_Source_Code/step2_data_ingestion/data_ingestion.py
[2025-08-17T02:01:13.038+0000] {logging_mixin.py:151} INFO - STDOUT: 
[2025-08-17T02:01:13.038+0000] {logging_mixin.py:151} INFO - STDERR: python: can't open file '/opt/***/02_Source_Code/step2_data_ingestion/data_ingestion.py': [Errno 2] No such file or directory
[2025-08-17T02:01:13.039+0000] {taskinstance.py:1943} ERROR - Task failed with exception
Traceback (most recent call last):
  File "/home/airflow/.local/lib/python3.8/site-packages/airflow/operators/python.py", line 192, in execute
    return_value = self.execute_callable()
  File "/home/airflow/.local/lib/python3.8/site-packages/airflow/operators/python.py", line 209, in execute_callable
    return self.python_callable(*self.op_args, **self.op_kwargs)
  File "/opt/airflow/dags/churn_pipeline_dag.py", line 12, in run_script
    result = subprocess.run(
  File "/usr/local/lib/python3.8/subprocess.py", line 516, in run
    raise CalledProcessError(retcode, process.args,
subprocess.CalledProcessError: Command '['python', '/opt/airflow/02_Source_Code/step2_data_ingestion/data_ingestion.py']' returned non-zero exit status 2.
[2025-08-17T02:01:13.061+0000] {taskinstance.py:1400} INFO - Marking task as FAILED. dag_id=churn_pipeline_dag, task_id=data_ingestion, execution_date=20250817T020109, start_date=20250817T020112, end_date=20250817T020113
[2025-08-17T02:01:13.080+0000] {standard_task_runner.py:104} ERROR - Failed to execute job 2 for task data_ingestion (Command '['python', '/opt/airflow/02_Source_Code/step2_data_ingestion/data_ingestion.py']' returned non-zero exit status 2.; 60)
[2025-08-17T02:01:13.101+0000] {local_task_job_runner.py:228} INFO - Task exited with return code 1
[2025-08-17T02:01:13.127+0000] {taskinstance.py:2784} INFO - 0 downstream tasks scheduled from follow-on schedule check
