[2025-08-17T01:28:11.600+0000] {local_task_job_runner.py:120} INFO - ::group::Pre task execution logs
[2025-08-17T01:28:11.639+0000] {taskinstance.py:2076} INFO - Dependencies all met for dep_context=non-requeueable deps ti=<TaskInstance: churn_pipeline_dag.feature_store manual__2025-08-17T01:27:53.715568+00:00 [queued]>
[2025-08-17T01:28:11.650+0000] {taskinstance.py:2076} INFO - Dependencies all met for dep_context=requeueable deps ti=<TaskInstance: churn_pipeline_dag.feature_store manual__2025-08-17T01:27:53.715568+00:00 [queued]>
[2025-08-17T01:28:11.651+0000] {taskinstance.py:2306} INFO - Starting attempt 1 of 1
[2025-08-17T01:28:11.669+0000] {taskinstance.py:2330} INFO - Executing <Task(PythonOperator): feature_store> on 2025-08-17 01:27:53.715568+00:00
[2025-08-17T01:28:11.680+0000] {warnings.py:112} WARNING - /home/***/.local/lib/python3.12/site-packages/***/task/task_runner/standard_task_runner.py:62: DeprecationWarning: This process (pid=138) is multi-threaded, use of fork() may lead to deadlocks in the child.
  pid = os.fork()

[2025-08-17T01:28:11.683+0000] {standard_task_runner.py:64} INFO - Started process 140 to run task
[2025-08-17T01:28:11.683+0000] {standard_task_runner.py:90} INFO - Running: ['***', 'tasks', 'run', 'churn_pipeline_dag', 'feature_store', 'manual__2025-08-17T01:27:53.715568+00:00', '--job-id', '30', '--raw', '--subdir', 'DAGS_FOLDER/churn_pipeline_dag.py', '--cfg-path', '/tmp/tmpqslbgekt']
[2025-08-17T01:28:11.686+0000] {standard_task_runner.py:91} INFO - Job 30: Subtask feature_store
[2025-08-17T01:28:11.757+0000] {task_command.py:426} INFO - Running <TaskInstance: churn_pipeline_dag.feature_store manual__2025-08-17T01:27:53.715568+00:00 [running]> on host 4d1e8e9a9fc3
[2025-08-17T01:28:11.927+0000] {taskinstance.py:2648} INFO - Exporting env vars: AIRFLOW_CTX_DAG_OWNER='***' AIRFLOW_CTX_DAG_ID='churn_pipeline_dag' AIRFLOW_CTX_TASK_ID='feature_store' AIRFLOW_CTX_EXECUTION_DATE='2025-08-17T01:27:53.715568+00:00' AIRFLOW_CTX_TRY_NUMBER='1' AIRFLOW_CTX_DAG_RUN_ID='manual__2025-08-17T01:27:53.715568+00:00'
[2025-08-17T01:28:11.930+0000] {taskinstance.py:430} INFO - ::endgroup::
[2025-08-17T01:28:13.245+0000] {logging_mixin.py:188} INFO - Feature metadata table initialized.
Features registered in metadata.
[2025-08-17T01:28:13.246+0000] {logging_mixin.py:188} INFO - ERRORS: Traceback (most recent call last):
  File "/home/***/.local/lib/python3.12/site-packages/pandas/io/sql.py", line 2262, in execute
    cur.execute(sql, *args)
sqlite3.OperationalError: no such table: customer_features

The above exception was the direct cause of the following exception:

Traceback (most recent call last):
  File "/opt/***/02_Source_Code/step7_feature_store/feature_store.py", line 102, in <module>
    df_train = get_features_for_training()
               ^^^^^^^^^^^^^^^^^^^^^^^^^^^
  File "/opt/***/02_Source_Code/step7_feature_store/feature_store.py", line 58, in get_features_for_training
    df = pd.read_sql("SELECT * FROM customer_features", conn)
         ^^^^^^^^^^^^^^^^^^^^^^^^^^^^^^^^^^^^^^^^^^^^^^^^^^^^
  File "/home/***/.local/lib/python3.12/site-packages/pandas/io/sql.py", line 654, in read_sql
    return pandas_sql.read_query(
           ^^^^^^^^^^^^^^^^^^^^^^
  File "/home/***/.local/lib/python3.12/site-packages/pandas/io/sql.py", line 2326, in read_query
    cursor = self.execute(sql, params)
             ^^^^^^^^^^^^^^^^^^^^^^^^^
  File "/home/***/.local/lib/python3.12/site-packages/pandas/io/sql.py", line 2274, in execute
    raise ex from exc
pandas.errors.DatabaseError: Execution failed on sql 'SELECT * FROM customer_features': no such table: customer_features
[2025-08-17T01:28:13.247+0000] {python.py:237} INFO - Done. Returned value was: None
[2025-08-17T01:28:13.248+0000] {taskinstance.py:441} INFO - ::group::Post task execution logs
[2025-08-17T01:28:13.259+0000] {taskinstance.py:1206} INFO - Marking task as SUCCESS. dag_id=churn_pipeline_dag, task_id=feature_store, run_id=manual__2025-08-17T01:27:53.715568+00:00, execution_date=20250817T012753, start_date=20250817T012811, end_date=20250817T012813
[2025-08-17T01:28:13.305+0000] {local_task_job_runner.py:243} INFO - Task exited with return code 0
[2025-08-17T01:28:13.327+0000] {taskinstance.py:3503} INFO - 1 downstream tasks scheduled from follow-on schedule check
[2025-08-17T01:28:13.330+0000] {local_task_job_runner.py:222} INFO - ::endgroup::
