[2025-08-17T05:05:57.076+0000] {taskinstance.py:1159} INFO - Dependencies all met for dep_context=non-requeueable deps ti=<TaskInstance: churn_pipeline_dag.data_preparation manual__2025-08-17T05:05:48.819770+00:00 [queued]>
[2025-08-17T05:05:57.084+0000] {taskinstance.py:1159} INFO - Dependencies all met for dep_context=requeueable deps ti=<TaskInstance: churn_pipeline_dag.data_preparation manual__2025-08-17T05:05:48.819770+00:00 [queued]>
[2025-08-17T05:05:57.085+0000] {taskinstance.py:1361} INFO - Starting attempt 1 of 1
[2025-08-17T05:05:57.097+0000] {taskinstance.py:1382} INFO - Executing <Task(PythonOperator): data_preparation> on 2025-08-17 05:05:48.819770+00:00
[2025-08-17T05:05:57.105+0000] {standard_task_runner.py:57} INFO - Started process 109 to run task
[2025-08-17T05:05:57.109+0000] {standard_task_runner.py:84} INFO - Running: ['***', 'tasks', 'run', 'churn_pipeline_dag', 'data_preparation', 'manual__2025-08-17T05:05:48.819770+00:00', '--job-id', '5', '--raw', '--subdir', 'DAGS_FOLDER/churn_pipeline_dag.py', '--cfg-path', '/tmp/tmpj52rclns']
[2025-08-17T05:05:57.110+0000] {standard_task_runner.py:85} INFO - Job 5: Subtask data_preparation
[2025-08-17T05:05:57.161+0000] {task_command.py:415} INFO - Running <TaskInstance: churn_pipeline_dag.data_preparation manual__2025-08-17T05:05:48.819770+00:00 [running]> on host d1471a41dc29
[2025-08-17T05:05:57.232+0000] {taskinstance.py:1660} INFO - Exporting env vars: AIRFLOW_CTX_DAG_OWNER='***' AIRFLOW_CTX_DAG_ID='churn_pipeline_dag' AIRFLOW_CTX_TASK_ID='data_preparation' AIRFLOW_CTX_EXECUTION_DATE='2025-08-17T05:05:48.819770+00:00' AIRFLOW_CTX_TRY_NUMBER='1' AIRFLOW_CTX_DAG_RUN_ID='manual__2025-08-17T05:05:48.819770+00:00'
[2025-08-17T05:05:58.797+0000] {taskinstance.py:1943} ERROR - Task failed with exception
Traceback (most recent call last):
  File "/home/airflow/.local/lib/python3.8/site-packages/airflow/operators/python.py", line 192, in execute
    return_value = self.execute_callable()
  File "/home/airflow/.local/lib/python3.8/site-packages/airflow/operators/python.py", line 209, in execute_callable
    return self.python_callable(*self.op_args, **self.op_kwargs)
  File "/opt/airflow/dags/churn_pipeline_dag.py", line 18, in run_script
    raise Exception(f"Script failed: {script_path}\n{result.stderr}")
Exception: Script failed: /opt/***/02_Source_Code/step5_data_preparation/data_preparation.py
Traceback (most recent call last):
  File "/opt/***/02_Source_Code/step5_data_preparation/data_preparation.py", line 110, in <module>
    run()
  File "/opt/***/02_Source_Code/step5_data_preparation/data_preparation.py", line 99, in run
    df = load_latest_transactions()
  File "/opt/***/02_Source_Code/step5_data_preparation/data_preparation.py", line 29, in load_latest_transactions
    files = [f for f in os.listdir(data_dir) if f.endswith(".csv")]
NameError: name 'os' is not defined

[2025-08-17T05:05:58.815+0000] {taskinstance.py:1400} INFO - Marking task as FAILED. dag_id=churn_pipeline_dag, task_id=data_preparation, execution_date=20250817T050548, start_date=20250817T050557, end_date=20250817T050558
[2025-08-17T05:05:58.830+0000] {standard_task_runner.py:104} ERROR - Failed to execute job 5 for task data_preparation (Script failed: /opt/***/02_Source_Code/step5_data_preparation/data_preparation.py
Traceback (most recent call last):
  File "/opt/***/02_Source_Code/step5_data_preparation/data_preparation.py", line 110, in <module>
    run()
  File "/opt/***/02_Source_Code/step5_data_preparation/data_preparation.py", line 99, in run
    df = load_latest_transactions()
  File "/opt/***/02_Source_Code/step5_data_preparation/data_preparation.py", line 29, in load_latest_transactions
    files = [f for f in os.listdir(data_dir) if f.endswith(".csv")]
NameError: name 'os' is not defined
; 109)
[2025-08-17T05:05:58.849+0000] {local_task_job_runner.py:228} INFO - Task exited with return code 1
[2025-08-17T05:05:58.872+0000] {taskinstance.py:2784} INFO - 0 downstream tasks scheduled from follow-on schedule check
