[2025-08-17T05:09:35.609+0000] {taskinstance.py:1159} INFO - Dependencies all met for dep_context=non-requeueable deps ti=<TaskInstance: churn_pipeline_dag.model_training manual__2025-08-17T05:09:20.049467+00:00 [queued]>
[2025-08-17T05:09:35.618+0000] {taskinstance.py:1159} INFO - Dependencies all met for dep_context=requeueable deps ti=<TaskInstance: churn_pipeline_dag.model_training manual__2025-08-17T05:09:20.049467+00:00 [queued]>
[2025-08-17T05:09:35.619+0000] {taskinstance.py:1361} INFO - Starting attempt 1 of 1
[2025-08-17T05:09:35.631+0000] {taskinstance.py:1382} INFO - Executing <Task(PythonOperator): model_training> on 2025-08-17 05:09:20.049467+00:00
[2025-08-17T05:09:35.638+0000] {standard_task_runner.py:57} INFO - Started process 180 to run task
[2025-08-17T05:09:35.642+0000] {standard_task_runner.py:84} INFO - Running: ['***', 'tasks', 'run', 'churn_pipeline_dag', 'model_training', 'manual__2025-08-17T05:09:20.049467+00:00', '--job-id', '18', '--raw', '--subdir', 'DAGS_FOLDER/churn_pipeline_dag.py', '--cfg-path', '/tmp/tmpygfaj5au']
[2025-08-17T05:09:35.644+0000] {standard_task_runner.py:85} INFO - Job 18: Subtask model_training
[2025-08-17T05:09:35.699+0000] {task_command.py:415} INFO - Running <TaskInstance: churn_pipeline_dag.model_training manual__2025-08-17T05:09:20.049467+00:00 [running]> on host 22bf1c6c1866
[2025-08-17T05:09:35.776+0000] {taskinstance.py:1660} INFO - Exporting env vars: AIRFLOW_CTX_DAG_OWNER='***' AIRFLOW_CTX_DAG_ID='churn_pipeline_dag' AIRFLOW_CTX_TASK_ID='model_training' AIRFLOW_CTX_EXECUTION_DATE='2025-08-17T05:09:20.049467+00:00' AIRFLOW_CTX_TRY_NUMBER='1' AIRFLOW_CTX_DAG_RUN_ID='manual__2025-08-17T05:09:20.049467+00:00'
[2025-08-17T05:09:35.872+0000] {taskinstance.py:1943} ERROR - Task failed with exception
Traceback (most recent call last):
  File "/home/airflow/.local/lib/python3.8/site-packages/airflow/operators/python.py", line 192, in execute
    return_value = self.execute_callable()
  File "/home/airflow/.local/lib/python3.8/site-packages/airflow/operators/python.py", line 209, in execute_callable
    return self.python_callable(*self.op_args, **self.op_kwargs)
  File "/opt/airflow/dags/churn_pipeline_dag.py", line 18, in run_script
    raise Exception(f"Script failed: {script_path}\n{result.stderr}")
Exception: Script failed: /opt/***/02_Source_Code/step8_model_training/model_building.py
/usr/local/bin/python: can't open file '/opt/***/02_Source_Code/step8_model_training/model_building.py': [Errno 2] No such file or directory

[2025-08-17T05:09:35.888+0000] {taskinstance.py:1400} INFO - Marking task as FAILED. dag_id=churn_pipeline_dag, task_id=model_training, execution_date=20250817T050920, start_date=20250817T050935, end_date=20250817T050935
[2025-08-17T05:09:35.902+0000] {standard_task_runner.py:104} ERROR - Failed to execute job 18 for task model_training (Script failed: /opt/***/02_Source_Code/step8_model_training/model_building.py
/usr/local/bin/python: can't open file '/opt/***/02_Source_Code/step8_model_training/model_building.py': [Errno 2] No such file or directory
; 180)
[2025-08-17T05:09:35.936+0000] {local_task_job_runner.py:228} INFO - Task exited with return code 1
[2025-08-17T05:09:35.957+0000] {taskinstance.py:2784} INFO - 0 downstream tasks scheduled from follow-on schedule check
