[2025-08-17T05:07:00.496+0000] {taskinstance.py:1159} INFO - Dependencies all met for dep_context=non-requeueable deps ti=<TaskInstance: churn_pipeline_dag.data_transformation manual__2025-08-17T05:06:49.919696+00:00 [queued]>
[2025-08-17T05:07:00.504+0000] {taskinstance.py:1159} INFO - Dependencies all met for dep_context=requeueable deps ti=<TaskInstance: churn_pipeline_dag.data_transformation manual__2025-08-17T05:06:49.919696+00:00 [queued]>
[2025-08-17T05:07:00.505+0000] {taskinstance.py:1361} INFO - Starting attempt 1 of 1
[2025-08-17T05:07:00.516+0000] {taskinstance.py:1382} INFO - Executing <Task(PythonOperator): data_transformation> on 2025-08-17 05:06:49.919696+00:00
[2025-08-17T05:07:00.524+0000] {standard_task_runner.py:57} INFO - Started process 209 to run task
[2025-08-17T05:07:00.527+0000] {standard_task_runner.py:84} INFO - Running: ['***', 'tasks', 'run', 'churn_pipeline_dag', 'data_transformation', 'manual__2025-08-17T05:06:49.919696+00:00', '--job-id', '10', '--raw', '--subdir', 'DAGS_FOLDER/churn_pipeline_dag.py', '--cfg-path', '/tmp/tmp6l_r24if']
[2025-08-17T05:07:00.529+0000] {standard_task_runner.py:85} INFO - Job 10: Subtask data_transformation
[2025-08-17T05:07:00.583+0000] {task_command.py:415} INFO - Running <TaskInstance: churn_pipeline_dag.data_transformation manual__2025-08-17T05:06:49.919696+00:00 [running]> on host d1471a41dc29
[2025-08-17T05:07:00.655+0000] {taskinstance.py:1660} INFO - Exporting env vars: AIRFLOW_CTX_DAG_OWNER='***' AIRFLOW_CTX_DAG_ID='churn_pipeline_dag' AIRFLOW_CTX_TASK_ID='data_transformation' AIRFLOW_CTX_EXECUTION_DATE='2025-08-17T05:06:49.919696+00:00' AIRFLOW_CTX_TRY_NUMBER='1' AIRFLOW_CTX_DAG_RUN_ID='manual__2025-08-17T05:06:49.919696+00:00'
[2025-08-17T05:07:00.757+0000] {taskinstance.py:1943} ERROR - Task failed with exception
Traceback (most recent call last):
  File "/home/airflow/.local/lib/python3.8/site-packages/airflow/operators/python.py", line 192, in execute
    return_value = self.execute_callable()
  File "/home/airflow/.local/lib/python3.8/site-packages/airflow/operators/python.py", line 209, in execute_callable
    return self.python_callable(*self.op_args, **self.op_kwargs)
  File "/opt/airflow/dags/churn_pipeline_dag.py", line 18, in run_script
    raise Exception(f"Script failed: {script_path}\n{result.stderr}")
Exception: Script failed: /opt/***/02_Source_Code/step6_data_transformation/data_transform.py
/usr/local/bin/python: can't open file '/opt/***/02_Source_Code/step6_data_transformation/data_transform.py': [Errno 2] No such file or directory

[2025-08-17T05:07:00.772+0000] {taskinstance.py:1400} INFO - Marking task as FAILED. dag_id=churn_pipeline_dag, task_id=data_transformation, execution_date=20250817T050649, start_date=20250817T050700, end_date=20250817T050700
[2025-08-17T05:07:00.787+0000] {standard_task_runner.py:104} ERROR - Failed to execute job 10 for task data_transformation (Script failed: /opt/***/02_Source_Code/step6_data_transformation/data_transform.py
/usr/local/bin/python: can't open file '/opt/***/02_Source_Code/step6_data_transformation/data_transform.py': [Errno 2] No such file or directory
; 209)
[2025-08-17T05:07:00.821+0000] {local_task_job_runner.py:228} INFO - Task exited with return code 1
[2025-08-17T05:07:00.845+0000] {taskinstance.py:2784} INFO - 0 downstream tasks scheduled from follow-on schedule check
