[2025-08-17T04:28:37.831+0000] {taskinstance.py:1159} INFO - Dependencies all met for dep_context=non-requeueable deps ti=<TaskInstance: churn_pipeline_dag.data_preparation manual__2025-08-17T04:28:29.487650+00:00 [queued]>
[2025-08-17T04:28:37.840+0000] {taskinstance.py:1159} INFO - Dependencies all met for dep_context=requeueable deps ti=<TaskInstance: churn_pipeline_dag.data_preparation manual__2025-08-17T04:28:29.487650+00:00 [queued]>
[2025-08-17T04:28:37.841+0000] {taskinstance.py:1361} INFO - Starting attempt 1 of 1
[2025-08-17T04:28:37.854+0000] {taskinstance.py:1382} INFO - Executing <Task(PythonOperator): data_preparation> on 2025-08-17 04:28:29.487650+00:00
[2025-08-17T04:28:37.861+0000] {standard_task_runner.py:57} INFO - Started process 103 to run task
[2025-08-17T04:28:37.865+0000] {standard_task_runner.py:84} INFO - Running: ['***', 'tasks', 'run', 'churn_pipeline_dag', 'data_preparation', 'manual__2025-08-17T04:28:29.487650+00:00', '--job-id', '13', '--raw', '--subdir', 'DAGS_FOLDER/churn_pipeline_dag.py', '--cfg-path', '/tmp/tmpw238a4s1']
[2025-08-17T04:28:37.867+0000] {standard_task_runner.py:85} INFO - Job 13: Subtask data_preparation
[2025-08-17T04:28:37.916+0000] {task_command.py:415} INFO - Running <TaskInstance: churn_pipeline_dag.data_preparation manual__2025-08-17T04:28:29.487650+00:00 [running]> on host 462815b998ae
[2025-08-17T04:28:37.986+0000] {taskinstance.py:1660} INFO - Exporting env vars: AIRFLOW_CTX_DAG_OWNER='***' AIRFLOW_CTX_DAG_ID='churn_pipeline_dag' AIRFLOW_CTX_TASK_ID='data_preparation' AIRFLOW_CTX_EXECUTION_DATE='2025-08-17T04:28:29.487650+00:00' AIRFLOW_CTX_TRY_NUMBER='1' AIRFLOW_CTX_DAG_RUN_ID='manual__2025-08-17T04:28:29.487650+00:00'
[2025-08-17T04:28:38.821+0000] {logging_mixin.py:151} INFO - ‚ùå Script failed: /opt/***/02_Source_Code/step5_data_preparation/data_preparation.py
[2025-08-17T04:28:38.822+0000] {logging_mixin.py:151} INFO - STDOUT: 
[2025-08-17T04:28:38.823+0000] {logging_mixin.py:151} INFO - STDERR: Traceback (most recent call last):
  File "/opt/***/02_Source_Code/step5_data_preparation/data_preparation.py", line 3, in <module>
    import matplotlib.pyplot as plt
ModuleNotFoundError: No module named 'matplotlib'
[2025-08-17T04:28:38.824+0000] {taskinstance.py:1943} ERROR - Task failed with exception
Traceback (most recent call last):
  File "/home/airflow/.local/lib/python3.8/site-packages/airflow/operators/python.py", line 192, in execute
    return_value = self.execute_callable()
  File "/home/airflow/.local/lib/python3.8/site-packages/airflow/operators/python.py", line 209, in execute_callable
    return self.python_callable(*self.op_args, **self.op_kwargs)
  File "/opt/airflow/dags/churn_pipeline_dag.py", line 12, in run_script
    result = subprocess.run(
  File "/usr/local/lib/python3.8/subprocess.py", line 516, in run
    raise CalledProcessError(retcode, process.args,
subprocess.CalledProcessError: Command '['python', '/opt/airflow/02_Source_Code/step5_data_preparation/data_preparation.py']' returned non-zero exit status 1.
[2025-08-17T04:28:38.841+0000] {taskinstance.py:1400} INFO - Marking task as FAILED. dag_id=churn_pipeline_dag, task_id=data_preparation, execution_date=20250817T042829, start_date=20250817T042837, end_date=20250817T042838
[2025-08-17T04:28:38.859+0000] {standard_task_runner.py:104} ERROR - Failed to execute job 13 for task data_preparation (Command '['python', '/opt/airflow/02_Source_Code/step5_data_preparation/data_preparation.py']' returned non-zero exit status 1.; 103)
[2025-08-17T04:28:38.882+0000] {local_task_job_runner.py:228} INFO - Task exited with return code 1
[2025-08-17T04:28:38.908+0000] {taskinstance.py:2784} INFO - 0 downstream tasks scheduled from follow-on schedule check
